04-06-2023 20:42:08 - ERROR - Exception in callback BaseProactorEventLoop._start_serving.<locals>.loop(<_OverlappedF...0.1', 57884))>) at C:\Program Files\WindowsApps\PythonSoftwareFoundation.Python.3.9_3.9.3568.0_x64__qbz5n2kfra8p0\lib\asyncio\proactor_events.py:816
handle: <Handle BaseProactorEventLoop._start_serving.<locals>.loop(<_OverlappedF...0.1', 57884))>) at C:\Program Files\WindowsApps\PythonSoftwareFoundation.Python.3.9_3.9.3568.0_x64__qbz5n2kfra8p0\lib\asyncio\proactor_events.py:816>
Traceback (most recent call last):
  File "C:\Program Files\WindowsApps\PythonSoftwareFoundation.Python.3.9_3.9.3568.0_x64__qbz5n2kfra8p0\lib\asyncio\events.py", line 80, in _run
    self._context.run(self._callback, *self._args)
  File "C:\Program Files\WindowsApps\PythonSoftwareFoundation.Python.3.9_3.9.3568.0_x64__qbz5n2kfra8p0\lib\asyncio\proactor_events.py", line 830, in loop
    self._make_socket_transport(
  File "C:\Program Files\WindowsApps\PythonSoftwareFoundation.Python.3.9_3.9.3568.0_x64__qbz5n2kfra8p0\lib\asyncio\proactor_events.py", line 637, in _make_socket_transport
    return _ProactorSocketTransport(self, sock, protocol, waiter,
  File "C:\Program Files\WindowsApps\PythonSoftwareFoundation.Python.3.9_3.9.3568.0_x64__qbz5n2kfra8p0\lib\asyncio\proactor_events.py", line 603, in __init__
    super().__init__(loop, sock, protocol, waiter, extra, server)
  File "C:\Program Files\WindowsApps\PythonSoftwareFoundation.Python.3.9_3.9.3568.0_x64__qbz5n2kfra8p0\lib\asyncio\proactor_events.py", line 185, in __init__
    super().__init__(loop, sock, protocol, waiter, extra, server)
  File "C:\Program Files\WindowsApps\PythonSoftwareFoundation.Python.3.9_3.9.3568.0_x64__qbz5n2kfra8p0\lib\asyncio\proactor_events.py", line 328, in __init__
    super().__init__(*args, **kw)
  File "C:\Program Files\WindowsApps\PythonSoftwareFoundation.Python.3.9_3.9.3568.0_x64__qbz5n2kfra8p0\lib\asyncio\proactor_events.py", line 65, in __init__
    self._server._attach()
  File "C:\Program Files\WindowsApps\PythonSoftwareFoundation.Python.3.9_3.9.3568.0_x64__qbz5n2kfra8p0\lib\asyncio\base_events.py", line 297, in _attach
    assert self._sockets is not None
AssertionError
04-06-2023 20:42:35 - ERROR - Task exception was never retrieved
future: <Task finished name='Task-9' coro=<IocpProactor.accept.<locals>.accept_coro() done, defined at C:\Program Files\WindowsApps\PythonSoftwareFoundation.Python.3.9_3.9.3568.0_x64__qbz5n2kfra8p0\lib\asyncio\windows_events.py:568> exception=OSError(22, 'The specified network name is no longer available', None, 64, None)>
Traceback (most recent call last):
  File "C:\Program Files\WindowsApps\PythonSoftwareFoundation.Python.3.9_3.9.3568.0_x64__qbz5n2kfra8p0\lib\asyncio\windows_events.py", line 571, in accept_coro
    await future
  File "C:\Program Files\WindowsApps\PythonSoftwareFoundation.Python.3.9_3.9.3568.0_x64__qbz5n2kfra8p0\lib\asyncio\windows_events.py", line 817, in _poll
    value = callback(transferred, key, ov)
  File "C:\Program Files\WindowsApps\PythonSoftwareFoundation.Python.3.9_3.9.3568.0_x64__qbz5n2kfra8p0\lib\asyncio\windows_events.py", line 560, in finish_accept
    ov.getresult()
OSError: [WinError 64] The specified network name is no longer available
04-06-2023 20:42:35 - ERROR - Accept failed on a socket
socket: <asyncio.TransportSocket fd=1032, family=AddressFamily.AF_INET, type=SocketKind.SOCK_STREAM, proto=6, laddr=('127.0.0.1', 8000)>
Traceback (most recent call last):
  File "C:\Program Files\WindowsApps\PythonSoftwareFoundation.Python.3.9_3.9.3568.0_x64__qbz5n2kfra8p0\lib\asyncio\proactor_events.py", line 819, in loop
    conn, addr = f.result()
  File "C:\Program Files\WindowsApps\PythonSoftwareFoundation.Python.3.9_3.9.3568.0_x64__qbz5n2kfra8p0\lib\asyncio\windows_events.py", line 571, in accept_coro
    await future
  File "C:\Program Files\WindowsApps\PythonSoftwareFoundation.Python.3.9_3.9.3568.0_x64__qbz5n2kfra8p0\lib\asyncio\windows_events.py", line 817, in _poll
    value = callback(transferred, key, ov)
  File "C:\Program Files\WindowsApps\PythonSoftwareFoundation.Python.3.9_3.9.3568.0_x64__qbz5n2kfra8p0\lib\asyncio\windows_events.py", line 560, in finish_accept
    ov.getresult()
OSError: [WinError 64] The specified network name is no longer available
04-06-2023 20:43:17 - ERROR - Exception in callback BaseProactorEventLoop._start_serving.<locals>.loop(<_OverlappedF...0.1', 58011))>) at C:\Program Files\WindowsApps\PythonSoftwareFoundation.Python.3.9_3.9.3568.0_x64__qbz5n2kfra8p0\lib\asyncio\proactor_events.py:816
handle: <Handle BaseProactorEventLoop._start_serving.<locals>.loop(<_OverlappedF...0.1', 58011))>) at C:\Program Files\WindowsApps\PythonSoftwareFoundation.Python.3.9_3.9.3568.0_x64__qbz5n2kfra8p0\lib\asyncio\proactor_events.py:816>
Traceback (most recent call last):
  File "C:\Program Files\WindowsApps\PythonSoftwareFoundation.Python.3.9_3.9.3568.0_x64__qbz5n2kfra8p0\lib\asyncio\events.py", line 80, in _run
    self._context.run(self._callback, *self._args)
  File "C:\Program Files\WindowsApps\PythonSoftwareFoundation.Python.3.9_3.9.3568.0_x64__qbz5n2kfra8p0\lib\asyncio\proactor_events.py", line 830, in loop
    self._make_socket_transport(
  File "C:\Program Files\WindowsApps\PythonSoftwareFoundation.Python.3.9_3.9.3568.0_x64__qbz5n2kfra8p0\lib\asyncio\proactor_events.py", line 637, in _make_socket_transport
    return _ProactorSocketTransport(self, sock, protocol, waiter,
  File "C:\Program Files\WindowsApps\PythonSoftwareFoundation.Python.3.9_3.9.3568.0_x64__qbz5n2kfra8p0\lib\asyncio\proactor_events.py", line 603, in __init__
    super().__init__(loop, sock, protocol, waiter, extra, server)
  File "C:\Program Files\WindowsApps\PythonSoftwareFoundation.Python.3.9_3.9.3568.0_x64__qbz5n2kfra8p0\lib\asyncio\proactor_events.py", line 185, in __init__
    super().__init__(loop, sock, protocol, waiter, extra, server)
  File "C:\Program Files\WindowsApps\PythonSoftwareFoundation.Python.3.9_3.9.3568.0_x64__qbz5n2kfra8p0\lib\asyncio\proactor_events.py", line 328, in __init__
    super().__init__(*args, **kw)
  File "C:\Program Files\WindowsApps\PythonSoftwareFoundation.Python.3.9_3.9.3568.0_x64__qbz5n2kfra8p0\lib\asyncio\proactor_events.py", line 65, in __init__
    self._server._attach()
  File "C:\Program Files\WindowsApps\PythonSoftwareFoundation.Python.3.9_3.9.3568.0_x64__qbz5n2kfra8p0\lib\asyncio\base_events.py", line 297, in _attach
    assert self._sockets is not None
AssertionError
04-06-2023 20:43:19 - ERROR - Exception in callback _ProactorBasePipeTransport._call_connection_lost(None)
handle: <Handle _ProactorBasePipeTransport._call_connection_lost(None)>
Traceback (most recent call last):
  File "C:\Program Files\WindowsApps\PythonSoftwareFoundation.Python.3.9_3.9.3568.0_x64__qbz5n2kfra8p0\lib\asyncio\events.py", line 80, in _run
    self._context.run(self._callback, *self._args)
  File "C:\Program Files\WindowsApps\PythonSoftwareFoundation.Python.3.9_3.9.3568.0_x64__qbz5n2kfra8p0\lib\asyncio\proactor_events.py", line 155, in _call_connection_lost
    self._protocol.connection_lost(exc)
  File "C:\Users\root\AppData\Local\Packages\PythonSoftwareFoundation.Python.3.9_qbz5n2kfra8p0\LocalCache\local-packages\Python39\site-packages\uvicorn\protocols\http\httptools_impl.py", line 152, in connection_lost
    self.transport.close()
AttributeError: 'NoneType' object has no attribute 'close'
04-06-2023 20:43:19 - ERROR - Exception in callback _ProactorBasePipeTransport._call_connection_lost(None)
handle: <Handle _ProactorBasePipeTransport._call_connection_lost(None)>
Traceback (most recent call last):
  File "C:\Program Files\WindowsApps\PythonSoftwareFoundation.Python.3.9_3.9.3568.0_x64__qbz5n2kfra8p0\lib\asyncio\events.py", line 80, in _run
    self._context.run(self._callback, *self._args)
  File "C:\Program Files\WindowsApps\PythonSoftwareFoundation.Python.3.9_3.9.3568.0_x64__qbz5n2kfra8p0\lib\asyncio\proactor_events.py", line 167, in _call_connection_lost
    server._detach()
  File "C:\Program Files\WindowsApps\PythonSoftwareFoundation.Python.3.9_3.9.3568.0_x64__qbz5n2kfra8p0\lib\asyncio\base_events.py", line 301, in _detach
    assert self._active_count > 0
AssertionError
